Workbook

Sheet Master_List
A1: S.no | B1: Player_Name | C1: player_type | D1: Position | E1: Club Name | F1: New Rating Overall | G1: Base Price | H1: Known As | I1: Full Name | J1: Overall | K1: Potential | L1: Value(in Euro) | M1: Positions Played | N1: Best Position | O1: Nationality | P1: Image Link | Q1: Age | R1: Height(in cm) | S1: Weight(in kg) | T1: TotalStats | U1: BaseStats | V1: Club Name | W1: Wage(in Euro) | X1: Release Clause | Y1: Club Position | Z1: Contract Until | AA1: Club Jersey Number | AB1: Joined On | AC1: On Loan | AD1: Preferred Foot | AE1: Weak Foot Rating | AF1: Skill Moves | AG1: International Reputation | AH1: National Team Name | AI1: National Team Image Link | AJ1: National Team Position | AK1: National Team Jersey Number | AL1: Attacking Work Rate | AM1: Defensive Work Rate | AN1: Pace Total | AO1: Shooting Total | AP1: Passing Total | AQ1: Dribbling Total | AR1: Defending Total | AS1: Physicality Total | AT1: Crossing | AU1: Finishing | AV1: Heading Accuracy | AW1: Short Passing | AX1: Volleys | AY1: Dribbling | AZ1: Curve | BA1: Freekick Accuracy | BB1: LongPassing | BC1: BallControl | BD1: Acceleration | BE1: Sprint Speed | BF1: Agility | BG1: Reactions | BH1: Balance | BI1: Shot Power | BJ1: Jumping | BK1: Stamina | BL1: Strength | BM1: Long Shots | BN1: Aggression | BO1: Interceptions | BP1: Positioning | BQ1: Vision | BR1: Penalties | BS1: Composure | BT1: Marking | BU1: Standing Tackle | BV1: Sliding Tackle | BW1: Goalkeeper Diving | BX1: Goalkeeper Handling | BY1: GoalkeeperKicking | BZ1: Goalkeeper Positioning | CA1: Goalkeeper Reflexes | CB1: ST Rating | CC1: LW Rating | CD1: LF Rating | CE1: CF Rating | CF1: RF Rating | CG1: RW Rating | CH1: CAM Rating | CI1: LM Rating | CJ1: CM Rating | CK1: RM Rating | CL1: LWB Rating | CM1: CDM Rating | CN1: RWB Rating | CO1: LB Rating | CP1: CB Rating | CQ1: RB Rating | CR1: GK Rating
A2: 1 | B2: Kevin De Bruyne | C2: Midfield | D2: CM | E2: Manchester City | F2: 91 | G2: 40 | H2: K. De Bruyne | I2: Kevin De Bruyne | J2: 91 | K2: 91 | L2: 107500000 | M2: CM,CAM | N2: CM | O2: Belgium | P2: https://cdn.sofifa.net/players/192/985/23_60.png | Q2: 31 | R2: 181 | S2: 70 | T2: 2303 | U2: 483 | V2: Manchester City | W2: 350000 | X2: 198900000 | Y2: CM | Z2: 2025 | AA2: 17 | AB2: 2015 | AC2: - | AD2: Right | AE2: 5 | AF2: 4 | AG2: 4 | AH2: Belgium | AI2: https://cdn.sofifa.net/flags/be.png | AJ2: RF | AK2: 7 | AL2: High | AM2: High | AN2: 74 | AO2: 88 | AP2: 93 | AQ2: 87 | AR2: 64 | AS2: 77 | AT2: 94 | AU2: 85 | AV2: 55 | AW2: 93 | AX2: 83 | AY2: 88 | AZ2: 89 | BA2: 83 | BB2: 93 | BC2: 90 | BD2: 76 | BE2: 73 | BF2: 76 | BG2: 91 | BH2: 78 | BI2: 92 | BJ2: 63 | BK2: 88 | BL2: 74 | BM2: 91 | BN2: 75 | BO2: 66 | BP2: 88 | BQ2: 94 | BR2: 83 | BS2: 89 | BT2: 68 | BU2: 65 | BV2: 53 | BW2: 15 | BX2: 13 | BY2: 5 | BZ2: 10 | CA2: 13 | CB2: 86 | CC2: 88 | CD2: 87 | CE2: 87 | CF2: 87 | CG2: 88 | CH2: 91 | CI2: 91 | CJ2: 91 | CK2: 91 | CL2: 82 | CM2: 82 | CN2: 82 | CO2: 78 | CP2: 72 | CQ2: 78 | CR2: 24
A3: 2 | B3: Casemiro | C3: Midfield | D3: CDM | E3: Manchester United | F3: 89 | G3: 40 | H3: Casemiro | I3: Carlos Henrique Venancio Casimiro | J3: 89 | K3: 89 | L3: 86000000 | M3: CDM | N3: CDM | O3: Brazil | P3: https://cdn.sofifa.net/players/200/145/23_60.png | Q3: 30 | R3: 185 | S3: 84 | T3: 2209 | U3: 460 | V3: Manchester United | W3: 240000 | X3: 163400000 | Y3: SUB | Z3: 2026 | AA3: 18 | AB3: 2022 | AC3: - | AD3: Right | AE3: 3 | AF3: 2 | AG3: 3 | AH3: - | AI3: https://cdn.sofifa.net/flags/br.png | AJ3: - | AK3: - | AL3: Medium | AM3: High | AN3: 63 | AO3: 73 | AP3: 75 | AQ3: 72 | AR3: 87 | AS3: 90 | AT3: 58 | AU3: 64 | AV3: 79 | AW3: 84 | AX3: 62 | AY3: 67 | AZ3: 62 | BA3: 74 | BB3: 83 | BC3: 78 | BD3: 60 | BE3: 66 | BF3: 61 | BG3: 87 | BH3: 66 | BI3: 88 | BJ3: 85 | BK3: 90 | BL3: 90 | BM3: 81 | BN3: 91 | BO3: 88 | BP3: 75 | BQ3: 75 | BR3: 66 | BS3: 84 | BT3: 87 | BU3: 88 | BV3: 87 | BW3: 13 | BX3: 14 | BY3: 16 | BZ3: 12 | CA3: 12 | CB3: 78 | CC3: 71 | CD3: 75 | CE3: 75 | CF3: 75 | CG3: 71 | CH3: 78 | CI3: 76 | CJ3: 84 | CK3: 76 | CL3: 83 | CM3: 89 | CN3: 83 | CO3: 84 | CP3: 89 | CQ3: 84 | CR3: 24
A4: 3 | B4: Luka Modric | C4: Midfield | D4: CM | E4: Real Madrid | F4: 88 | G4: 40 | H4: L. Modrić | I4: Luka Modrić | J4: 88 | K4: 88 | L4: 29000000 | M4: CM | N4: CM | O4: Croatia | P4: https://cdn.sofifa.net/players/177/003/23_60.png | Q4: 36 | R4: 172 | S4: 66 | T4: 2257 | U4: 464 | V4: Real Madrid CF | W4: 230000 | X4: 59500000 | Y4: CM | Z4: 2023 | AA4: 10 | AB4: 2012 | AC4: - | AD4: Right | AE4: 4 | AF4: 4 | AG4: 4 | AH4: Croatia | AI4: https://cdn.sofifa.net/flags/hr.png | AJ4: CM | AK4: 10 | AL4: Medium | AM4: Medium | AN4: 73 | AO4: 76 | AP4: 89 | AQ4: 88 | AR4: 72 | AS4: 66 | AT4: 86 | AU4: 72 | AV4: 55 | AW4: 91 | AX4: 76 | AY4: 85 | AZ4: 85 | BA4: 78 | BB4: 92 | BC4: 90 | BD4: 76 | BE4: 70 | BF4: 91 | BG4: 88 | BH4: 92 | BI4: 79 | BJ4: 67 | BK4: 83 | BL4: 58 | BM4: 82 | BN4: 62 | BO4: 80 | BP4: 78 | BQ4: 90 | BR4: 82 | BS4: 92 | BT4: 70 | BU4: 75 | BV4: 72 | BW4: 13 | BX4: 9 | BY4: 7 | BZ4: 14 | CA4: 9 | CB4: 79 | CC4: 83 | CD4: 82 | CE4: 82 | CF4: 82 | CG4: 83 | CH4: 88 | CI4: 87 | CJ4: 88 | CK4: 87 | CL4: 84 | CM4: 84 | CN4: 84 | CO4: 82 | CP4: 75 | CQ4: 82 | CR4: 22
A5: 4 | B5: Toni Kroos | C5: Midfield | D5: CM | E5: Real Madrid | F5: 88 | G5: 40 | H5: T. Kroos | I5: Toni Kroos | J5: 88 | K5: 88 | L5: 72000000 | M5: CM | N5: CM | O5: Germany | P5: https://cdn.sofifa.net/players/182/521/23_60.png | Q5: 32 | R5: 183 | S5: 76 | T5: 2147 | U5: 444 | V5: Real Madrid CF | W5: 310000 | X5: 147600000 | Y5: CM | Z5: 2023 | AA5: 8 | AB5: 2014 | AC5: - | AD5: Right | AE5: 5 | AF5: 3 | AG5: 4 | AH5: - | AI5: https://cdn.sofifa.net/flags/de.png | AJ5: - | AK5: - | AL5: Medium | AM5: Medium | AN5: 53 | AO5: 81 | AP5: 90 | AQ5: 81 | AR5: 71 | AS5: 68 | AT5: 88 | AU5: 77 | AV5: 58 | AW5: 93 | AX5: 82 | AY5: 80 | AZ5: 86 | BA5: 84 | BB5: 93 | BC5: 88 | BD5: 55 | BE5: 52 | BF5: 63 | BG5: 90 | BH5: 71 | BI5: 89 | BJ5: 32 | BK5: 75 | BL5: 72 | BM5: 86 | BN5: 60 | BO5: 80 | BP5: 76 | BQ5: 89 | BR5: 73 | BS5: 88 | BT5: 71 | BU5: 73 | BV5: 60 | BW5: 10 | BX5: 11 | BY5: 13 | BZ5: 7 | CA5: 10 | CB5: 80 | CC5: 80 | CD5: 81 | CE5: 81 | CF5: 81 | CG5: 80 | CH5: 86 | CI5: 84 | CJ5: 88 | CK5: 84 | CL5: 80 | CM5: 84 | CN5: 80 | CO5: 77 | CP5: 74 | CQ5: 77 | CR5: 22
A6: 5 | B6: Bernardo Silva | C6: Midfield | D6: CM | E6: Manchester City | F6: 88 | G6: 40 | H6: Bernardo Silva | I6: Bernardo Mota Carvalho e Silva | J6: 88 | K6: 88 | L6: 97500000 | M6: CAM,CM | N6: CAM | O6: Portugal | P6: https://cdn.sofifa.net/players/218/667/23_60.png | Q6: 27 | R6: 173 | S6: 64 | T6: 2185 | U6: 460 | V6: Manchester City | W6: 260000 | X6: 180400000 | Y6: RW | Z6: 2025 | AA6: 20 | AB6: 2017 | AC6: - | AD6: Left | AE6: 3 | AF6: 4 | AG6: 2 | AH6: Portugal | AI6: https://cdn.sofifa.net/flags/pt.png | AJ6: CM | AK6: 10 | AL6: High | AM6: High | AN6: 77 | AO6: 78 | AP6: 84 | AQ6: 92 | AR6: 61 | AS6: 68 | AT6: 85 | AU6: 79 | AV6: 51 | AW6: 89 | AX6: 78 | AY6: 92 | AZ6: 85 | BA6: 67 | BB6: 77 | BC6: 91 | BD6: 84 | BE6: 71 | BF6: 94 | BG6: 87 | BH6: 92 | BI6: 79 | BJ6: 51 | BK6: 93 | BL6: 54 | BM6: 78 | BN6: 75 | BO6: 60 | BP6: 83 | BQ6: 85 | BR6: 68 | BS6: 90 | BT6: 59 | BU6: 71 | BV6: 53 | BW6: 9 | BX6: 10 | BY6: 14 | BZ6: 12 | CA6: 9 | CB6: 80 | CC6: 86 | CD6: 84 | CE6: 84 | CF6: 84 | CG6: 86 | CH6: 88 | CI6: 88 | CJ6: 86 | CK6: 88 | CL6: 79 | CM6: 77 | CN6: 79 | CO6: 75 | CP6: 67 | CQ6: 75 | CR6: 21
A7: 6 | B7: Frenkie de Jong | C7: Midfield | D7: CM | E7: Barcelona | F7: 87 | G7: 30 | H7: F. de Jong | I7: Frenkie de Jong | J7: 87 | K7: 92 | L7: 116500000 | M7: CM | N7: CM | O7: Netherlands | P7: https://cdn.sofifa.net/players/228/702/23_60.png | Q7: 25 | R7: 180 | S7: 74 | T7: 2238 | U7: 479 | V7: FC Barcelona | W7: 230000 | X7: 247600000 | Y7: CM | Z7: 2026 | AA7: 21 | AB7: 2019 | AC7: - | AD7: Right | AE7: 3 | AF7: 4 | AG7: 3 | AH7: Netherlands | AI7: https://cdn.sofifa.net/flags/nl.png | AJ7: CDM | AK7: 21 | AL7: High | AM7: Medium | AN7: 82 | AO7: 69 | AP7: 86 | AQ7: 87 | AR7: 77 | AS7: 78 | AT7: 78 | AU7: 72 | AV7: 72 | AW7: 91 | AX7: 70 | AY7: 87 | AZ7: 84 | BA7: 64 | BB7: 89 | BC7: 89 | BD7: 80 | BE7: 83 | BF7: 87 | BG7: 88 | BH7: 79 | BI7: 68 | BJ7: 76 | BK7: 89 | BL7: 74 | BM7: 66 | BN7: 74 | BO7: 82 | BP7: 77 | BQ7: 88 | BR7: 53 | BS7: 90 | BT7: 76 | BU7: 76 | BV7: 77 | BW7: 7 | BX7: 13 | BY7: 10 | BZ7: 10 | CA7: 9 | CB7: 81 | CC7: 83 | CD7: 82 | CE7: 82 | CF7: 82 | CG7: 83 | CH7: 88 | CI7: 88 | CJ7: 89 | CK7: 88 | CL7: 86 | CM7: 87 | CN7: 86 | CO7: 85 | CP7: 81 | CQ7: 85 | CR7: 21
A8: 7 | B8: Leon Goretzka | C8: Midfield | D8: CM | E8: Bayern Munich | F8: 87 | G8: 30 | H8: L. Goretzka | I8: Leon Goretzka | J8: 87 | K8: 88 | L8: 91000000 | M8: CM,CDM | N8: CM | O8: Germany | P8: https://cdn.sofifa.net/players/209/658/23_60.png | Q8: 27 | R8: 189 | S8: 82 | T8: 2312 | U8: 492 | V8: FC Bayern München | W8: 115000 | X8: 157000000 | Y8: CDM | Z8: 2026 | AA8: 8 | AB8: 2018 | AC8: - | AD8: Right | AE8: 4 | AF8: 3 | AG8: 4 | AH8: Germany | AI8: https://cdn.sofifa.net/flags/de.png | AJ8: SUB | AK8: 8 | AL8: High | AM8: Medium | AN8: 78 | AO8: 82 | AP8: 82 | AQ8: 83 | AR8: 81 | AS8: 86 | AT8: 75 | AU8: 82 | AV8: 86 | AW8: 86 | AX8: 71 | AY8: 84 | AZ8: 76 | BA8: 75 | BB8: 85 | BC8: 86 | BD8: 78 | BE8: 78 | BF8: 76 | BG8: 87 | BH8: 73 | BI8: 85 | BJ8: 80 | BK8: 86 | BL8: 88 | BM8: 86 | BN8: 82 | BO8: 86 | BP8: 85 | BQ8: 84 | BR8: 60 | BS8: 82 | BT8: 74 | BU8: 84 | BV8: 78 | BW8: 13 | BX8: 8 | BY8: 15 | BZ8: 11 | CA8: 9 | CB8: 87 | CC8: 83 | CD8: 84 | CE8: 84 | CF8: 84 | CG8: 83 | CH8: 87 | CI8: 86 | CJ8: 88 | CK8: 86 | CL8: 85 | CM8: 87 | CN8: 85 | CO8: 85 | CP8: 86 | CQ8: 85 | CR8: 22
A9: 8 | B9: Verratti | C9: Midfield | D9: CM | E9: PSG | F9: 87 | G9: 30 | H9: M. Verratti | I9: Marco Verratti | J9: 87 | K9: 87 | L9: 77500000 | M9: CM,CAM | N9: CM | O9: Italy | P9: https://cdn.sofifa.net/players/199/556/23_60.png | Q9: 29 | R9: 165 | S9: 60 | T9: 2189 | U9: 444 | V9: Paris Saint-Germain | W9: 155000 | X9: 143400000 | Y9: CM | Z9: 2024 | AA9: 6 | AB9: 2012 | AC9: - | AD9: Right | AE9: 4 | AF9: 4 | AG9: 3 | AH9: Italy | AI9: https://cdn.sofifa.net/flags/it.png | AJ9: CM | AK9: 6 | AL9: Medium | AM9: High | AN9: 60 | AO9: 61 | AP9: 87 | AQ9: 91 | AR9: 79 | AS9: 66 | AT9: 82 | AU9: 60 | AV9: 57 | AW9: 90 | AX9: 64 | AY9: 91 | AZ9: 85 | BA9: 64 | BB9: 89 | BC9: 92 | BD9: 65 | BE9: 55 | BF9: 90 | BG9: 87 | BH9: 93 | BI9: 60 | BJ9: 66 | BK9: 75 | BL9: 53 | BM9: 58 | BN9: 89 | BO9: 85 | BP9: 78 | BQ9: 89 | BR9: 64 | BS9: 94 | BT9: 78 | BU9: 82 | BV9: 84 | BW9: 12 | BX9: 12 | BY9: 15 | BZ9: 15 | CA9: 10 | CB9: 74 | CC9: 80 | CD9: 79 | CE9: 79 | CF9: 79 | CG9: 80 | CH9: 86 | CI9: 85 | CJ9: 87 | CK9: 85 | CL9: 85 | CM9: 87 | CN9: 85 | CO9: 83 | CP9: 80 | CQ9: 83 | CR9: 24
A10: 9 | B10: Bruno Fernandes | C10: Midfield | D10: CAM | E10: Manchester United | F10: 86 | G10: 30 | H10: Bruno Fernandes | I10: Bruno Miguel Borges Fernandes | J10: 86 | K10: 86 | L10: 72500000 | M10: CAM,CM | N10: CAM | O10: Portugal | P10: https://cdn.sofifa.net/players/212/198/23_60.png | Q10: 27 | R10: 179 | S10: 69 | T10: 2305 | U10: 470 | V10: Manchester United | W10: 190000 | X10: 137800000 | Y10: CAM | Z10: 2026 | AA10: 8 | AB10: 2020 | AC10: - | AD10: Right | AE10: 3 | AF10: 4 | AG10: 3 | AH10: Portugal | AI10: https://cdn.sofifa.net/flags/pt.png | AJ10: CM | AK10: 11 | AL10: High | AM10: High | AN10: 72 | AO10: 86 | AP10: 88 | AQ10: 81 | AR10: 67 | AS10: 76 | AT10: 85 | AU10: 83 | AV10: 64 | AW10: 88 | AX10: 87 | AY10: 79 | AZ10: 87 | BA10: 85 | BB10: 88 | BC10: 84 | BD10: 75 | BE10: 69 | BF10: 78 | BG10: 91 | BH10: 79 | BI10: 88 | BJ10: 71 | BK10: 92 | BL10: 66 | BM10: 88 | BN10: 80 | BO10: 64 | BP10: 86 | BQ10: 91 | BR10: 90 | BS10: 79 | BT10: 66 | BU10: 73 | BV10: 65 | BW10: 12 | BX10: 14 | BY10: 15 | BZ10: 8 | CA10: 14 | CB10: 84 | CC10: 83 | CD10: 84 | CE10: 84 | CF10: 84 | CG10: 83 | CH10: 86 | CI10: 86 | CJ10: 86 | CK10: 86 | CL10: 81 | CM10: 82 | CN10: 81 | CO10: 79 | CP10: 74 | CQ10: 79 | CR10: 24
A11: 10 | B11: Jude Bellingham | C11: Midfield | D11: CM | E11: Real Madrid | F11: 86 | G11: 30 | H11: J. Bellingham | I11: Jude Bellingham | J11: 84 | K11: 91 | L11: 81500000 | M11: CM,LM | N11: CM | O11: England | P11: https://cdn.sofifa.net/players/252/371/23_60.png | Q11: 19 | R11: 186 | S11: 75 | T11: 2182 | U11: 469 | V11: Borussia Dortmund | W11: 41000 | X11: 154900000 | Y11: CDM | Z11: 2025 | AA11: 22 | AB11: 2020 | AC11: - | AD11: Right | AE11: 4 | AF11: 4 | AG11: 2 | AH11: England | AI11: https://cdn.sofifa.net/flags/gb-eng.png | AJ11: SUB | AK11: 26 | AL11: High | AM11: High | AN11: 75 | AO11: 75 | AP11: 78 | AQ11: 84 | AR11: 77 | AS11: 80 | AT11: 66 | AU11: 77 | AV11: 67 | AW11: 84 | AX11: 71 | AY11: 85 | AZ11: 68 | BA11: 49 | BB11: 82 | BC11: 84 | BD11: 78 | BE11: 73 | BF11: 81 | BG11: 84 | BH11: 79 | BI11: 78 | BJ11: 76 | BK11: 89 | BL11: 74 | BM11: 74 | BN11: 85 | BO11: 80 | BP11: 77 | BQ11: 84 | BR11: 56 | BS11: 79 | BT11: 79 | BU11: 78 | BV11: 76 | BW11: 14 | BX11: 11 | BY11: 10 | BZ11: 5 | CA11: 8 | CB11: 80 | CC11: 80 | CD11: 81 | CE11: 81 | CF11: 81 | CG11: 80 | CH11: 84 | CI11: 82 | CJ11: 85 | CK11: 82 | CL11: 81 | CM11: 84 | CN11: 81 | CO11: 80 | CP11: 80 | CQ11: 80 | CR11: 20
A12: 11 | B12: Federico Valverde | C12: Midfield | D12: CM | E12: Real Madrid | F12: 86 | G12: 30 | H12: F. Valverde | I12: Federico Valverde | J12: 84 | K12: 90 | L12: 66000000 | M12: CM,RW | N12: CM | O12: Uruguay | P12: https://cdn.sofifa.net/players/239/053/23_60.png | Q12: 23 | R12: 182 | S12: 78 | T12: 2192 | U12: 478 | V12: Real Madrid CF | W12: 175000 | X12: 148500000 | Y12: SUB | Z12: 2027 | AA12: 15 | AB12: 2016 | AC12: - | AD12: Right | AE12: 4 | AF12: 3 | AG12: 1 | AH12: - | AI12: https://cdn.sofifa.net/flags/uy.png | AJ12: - | AK12: - | AL12: High | AM12: High | AN12: 87 | AO12: 74 | AP12: 80 | AQ12: 79 | AR12: 78 | AS12: 80 | AT12: 70 | AU12: 69 | AV12: 59 | AW12: 86 | AX12: 70 | AY12: 78 | AZ12: 70 | BA12: 66 | BB12: 85 | BC12: 83 | BD12: 82 | BE12: 91 | BF12: 76 | BG12: 84 | BH12: 68 | BI12: 83 | BJ12: 62 | BK12: 86 | BL12: 79 | BM12: 81 | BN12: 81 | BO12: 81 | BP12: 78 | BQ12: 81 | BR12: 59 | BS12: 82 | BT12: 79 | BU12: 81 | BV12: 79 | BW12: 6 | BX12: 10 | BY12: 6 | BZ12: 15 | CA12: 8 | CB12: 79 | CC12: 80 | CD12: 80 | CE12: 80 | CF12: 80 | CG12: 80 | CH12: 83 | CI12: 83 | CJ12: 85 | CK12: 83 | CL12: 83 | CM12: 84 | CN12: 83 | CO12: 83 | CP12: 80 | CQ12: 83 | CR12: 20
A13: 12 | B13: Fabinho | C13: Midfield | D13: CDM | E13: Al-Ittihad | F13: 86 | G13: 30 | H13: Fabinho | I13: Fábio Henrique Tavares | J13: 87 | K13: 88 | L13: 77000000 | M13: CDM,CB | N13: CDM | O13: Brazil | P13: https://cdn.sofifa.net/players/209/499/23_60.png | Q13: 28 | R13: 188 | S13: 78 | T13: 2165 | U13: 459 | V13: Liverpool | W13: 185000 | X13: 148200000 | Y13: CDM | Z13: 2026 | AA13: 3 | AB13: 2018 | AC13: - | AD13: Right | AE13: 2 | AF13: 3 | AG13: 3 | AH13: - | AI13: https://cdn.sofifa.net/flags/br.png | AJ13: - | AK13: - | AL13: Medium | AM13: High | AN13: 66 | AO13: 69 | AP13: 78 | AQ13: 77 | AR13: 86 | AS13: 83 | AT13: 75 | AU13: 63 | AV13: 75 | AW13: 84 | AX13: 47 | AY13: 78 | AZ13: 71 | BA13: 53 | BB13: 82 | BC13: 81 | BD13: 64 | BE13: 68 | BF13: 63 | BG13: 86 | BH13: 64 | BI13: 81 | BJ13: 75 | BK13: 88 | BL13: 81 | BM13: 70 | BN13: 85 | BO13: 88 | BP13: 70 | BQ13: 76 | BR13: 90 | BS13: 85 | BT13: 86 | BU13: 88 | BV13: 86 | BW13: 13 | BX13: 12 | BY13: 6 | BZ13: 8 | CA13: 8 | CB13: 77 | CC13: 75 | CD13: 75 | CE13: 75 | CF13: 75 | CG13: 75 | CH13: 79 | CI13: 80 | CJ13: 84 | CK13: 80 | CL13: 85 | CM13: 88 | CN13: 85 | CO13: 85 | CP13: 87 | CQ13: 85 | CR13: 21
A14: 13 | B14: Nicolò Barella | C14: Midfield | D14: CM | E14: Inter Milan | F14: 86 | G14: 30 | H14: N. Barella | I14: Nicolò Barella | J14: 86 | K14: 89 | L14: 89500000 | M14: CM | N14: CM | O14: Italy | P14: https://cdn.sofifa.net/players/224/232/23_60.png | Q14: 25 | R14: 172 | S14: 68 | T14: 2296 | U14: 480 | V14: Inter | W14: 110000 | X14: 154400000 | Y14: CM | Z14: 2026 | AA14: 23 | AB14: 2020 | AC14: - | AD14: Right | AE14: 3 | AF14: 3 | AG14: 3 | AH14: Italy | AI14: https://cdn.sofifa.net/flags/it.png | AJ14: CM | AK14: 18 | AL14: High | AM14: High | AN14: 79 | AO14: 76 | AP14: 83 | AQ14: 84 | AR14: 77 | AS14: 81 | AT14: 79 | AU14: 73 | AV14: 53 | AW14: 86 | AX14: 80 | AY14: 80 | AZ14: 79 | BA14: 67 | BB14: 85 | BC14: 87 | BD14: 80 | BE14: 78 | BF14: 90 | BG14: 88 | BH14: 90 | BI14: 77 | BJ14: 78 | BK14: 94 | BL14: 73 | BM14: 79 | BN14: 84 | BO14: 83 | BP14: 81 | BQ14: 86 | BR14: 73 | BS14: 86 | BT14: 79 | BU14: 79 | BV14: 81 | BW14: 11 | BX14: 5 | BY14: 13 | BZ14: 14 | CA14: 11 | CB14: 80 | CC14: 82 | CD14: 81 | CE14: 81 | CF14: 81 | CG14: 82 | CH14: 86 | CI14: 86 | CJ14: 88 | CK14: 86 | CL14: 86 | CM14: 87 | CN14: 86 | CO14: 85 | CP14: 81 | CQ14: 85 | CR14: 22
A15: 14 | B15: Milinkovic Savic | C15: Midfield | D15: CM | E15: Al-Nasar | F15: 86 | G15: 30 | H15: V. Milinković-Savić | I15: Vanja Milinković-Savić | J15: 73 | K15: 77 | L15: 3300000 | M15: GK | N15: GK | O15: Serbia | P15: https://cdn.sofifa.net/players/224/836/23_60.png | Q15: 25 | R15: 202 | S15: 90 | T15: 1330 | U15: 412 | V15: Torino F.C. | W15: 22000 | X15: 6200000 | Y15: GK | Z15: 2024 | AA15: 32 | AB15: 2017 | AC15: - | AD15: Right | AE15: 3 | AF15: 1 | AG15: 1 | AH15: - | AI15: - | AJ15: - | AK15: - | AL15: Medium | AM15: Medium | AN15: 73 | AO15: 71 | AP15: 78 | AQ15: 73 | AR15: 43 | AS15: 74 | AT15: 18 | AU15: 20 | AV15: 12 | AW15: 31 | AX15: 16 | AY15: 15 | AZ15: 55 | BA15: 59 | BB15: 30 | BC15: 18 | BD15: 41 | BE15: 45 | BF15: 38 | BG15: 63 | BH15: 38 | BI15: 59 | BJ15: 58 | BK15: 33 | BL15: 73 | BM15: 45 | BN15: 34 | BO15: 21 | BP15: 12 | BQ15: 58 | BR15: 24 | BS15: 65 | BT15: 11 | BU15: 15 | BV15: 19 | BW15: 73 | BX15: 71 | BY15: 78 | BZ15: 74 | CA15: 73 | CB15: 33 | CC15: 29 | CD15: 31 | CE15: 31 | CF15: 31 | CG15: 29 | CH15: 34 | CI15: 31 | CJ15: 34 | CK15: 31 | CL15: 29 | CM15: 31 | CN15: 29 | CO15: 28 | CP15: 30 | CQ15: 28 | CR15: 74
A16: 15 | B16: Thiago Alcantara | C16: Midfield | D16: CDM | E16: Liverpool | F16: 86 | G16: 30 | H16: Thiago | I16: Thiago Alcântara | J16: 86 | K16: 86 | L16: 55500000 | M16: CM | N16: CM | O16: Spain | P16: https://cdn.sofifa.net/players/189/509/23_60.png | Q16: 31 | R16: 174 | S16: 70 | T16: 2225 | U16: 451 | V16: Liverpool | W16: 180000 | X16: 102700000 | Y16: CM | Z16: 2024 | AA16: 6 | AB16: 2020 | AC16: - | AD16: Right | AE16: 3 | AF16: 5 | AG16: 3 | AH16: - | AI16: https://cdn.sofifa.net/flags/es.png | AJ16: - | AK16: - | AL16: Medium | AM16: Medium | AN16: 61 | AO16: 72 | AP16: 87 | AQ16: 90 | AR16: 72 | AS16: 69 | AT16: 78 | AU16: 68 | AV16: 54 | AW16: 91 | AX16: 82 | AY16: 89 | AZ16: 85 | BA16: 77 | BB16: 89 | BC16: 92 | BD16: 69 | BE16: 55 | BF16: 90 | BG16: 84 | BH16: 90 | BI16: 75 | BJ16: 86 | BK16: 76 | BL16: 60 | BM16: 73 | BN16: 80 | BO16: 82 | BP16: 75 | BQ16: 88 | BR16: 75 | BS16: 90 | BT16: 68 | BU16: 74 | BV16: 74 | BW16: 6 | BX16: 11 | BY16: 7 | BZ16: 9 | CA16: 13 | CB16: 77 | CC16: 81 | CD16: 80 | CE16: 80 | CF16: 80 | CG16: 81 | CH16: 86 | CI16: 85 | CJ16: 86 | CK16: 85 | CL16: 81 | CM16: 84 | CN16: 81 | CO16: 79 | CP16: 76 | CQ16: 79 | CR16: 21
A17: 16 | B17: Thomas Muller | C17: Midfield | D17: CM | E17: Bayern Munich | F17: 85 | G17: 30 | H17: T. Müller | I17: Thomas Müller | J17: 87 | K17: 87 | L17: 63000000 | M17: CAM,CF | N17: CAM | O17: Germany | P17: https://cdn.sofifa.net/players/189/596/23_60.png | Q17: 32 | R17: 185 | S17: 76 | T17: 2140 | U17: 443 | V17: FC Bayern München | W17: 115000 | X17: 104000000 | Y17: CAM | Z17: 2024 | AA17: 25 | AB17: 2008 | AC17: - | AD17: Right | AE17: 4 | AF17: 3 | AG17: 4 | AH17: Germany | AI17: https://cdn.sofifa.net/flags/de.png | AJ17: CAM | AK17: 13 | AL17: High | AM17: High | AN17: 69 | AO17: 84 | AP17: 83 | AQ17: 80 | AR17: 56 | AS17: 71 | AT17: 85 | AU17: 88 | AV17: 81 | AW17: 85 | AX17: 84 | AY17: 77 | AZ17: 81 | BA17: 59 | BB17: 79 | BC17: 84 | BD17: 66 | BE17: 71 | BF17: 72 | BG17: 94 | BH17: 71 | BI17: 78 | BJ17: 77 | BK17: 86 | BL17: 66 | BM17: 82 | BN17: 62 | BO17: 58 | BP17: 96 | BQ17: 86 | BR17: 70 | BS17: 84 | BT17: 47 | BU17: 57 | BV17: 46 | BW17: 6 | BX17: 7 | BY17: 11 | BZ17: 14 | CA17: 14 | CB17: 86 | CC17: 83 | CD17: 84 | CE17: 84 | CF17: 84 | CG17: 83 | CH17: 87 | CI17: 86 | CJ17: 85 | CK17: 86 | CL17: 74 | CM17: 74 | CN17: 74 | CO17: 72 | CP17: 66 | CQ17: 72 | CR17: 23
A18: 17 | B18: Ilkay Gundogan | C18: Midfield | D18: CM | E18: Barcelona | F18: 85 | G18: 30 | H18: İ. Gündoğan | I18: İlkay Gündoğan | J18: 85 | K18: 85 | L18: 44000000 | M18: CM,CDM | N18: CM | O18: Germany | P18: https://cdn.sofifa.net/players/186/942/23_60.png | Q18: 31 | R18: 180 | S18: 80 | T18: 2195 | U18: 458 | V18: Manchester City | W18: 185000 | X18: 81400000 | Y18: CM | Z18: 2023 | AA18: 8 | AB18: 2016 | AC18: - | AD18: Right | AE18: 4 | AF18: 4 | AG18: 3 | AH18: Germany | AI18: https://cdn.sofifa.net/flags/de.png | AJ18: CDM | AK18: 21 | AL18: High | AM18: Medium | AN18: 64 | AO18: 80 | AP18: 85 | AQ18: 85 | AR18: 72 | AS18: 72 | AT18: 78 | AU18: 81 | AV18: 50 | AW18: 88 | AX18: 75 | AY18: 85 | AZ18: 86 | BA18: 80 | BB18: 85 | BC18: 90 | BD18: 66 | BE18: 63 | BF18: 77 | BG18: 86 | BH18: 77 | BI18: 79 | BJ18: 61 | BK18: 74 | BL18: 73 | BM18: 81 | BN18: 70 | BO18: 75 | BP18: 83 | BQ18: 86 | BR18: 80 | BS18: 87 | BT18: 76 | BU18: 75 | BV18: 67 | BW18: 11 | BX18: 14 | BY18: 5 | BZ18: 5 | CA18: 13 | CB18: 81 | CC18: 82 | CD18: 82 | CE18: 82 | CF18: 82 | CG18: 82 | CH18: 85 | CI18: 85 | CJ18: 85 | CK18: 85 | CL18: 80 | CM18: 83 | CN18: 80 | CO18: 78 | CP18: 75 | CQ18: 78 | CR18: 22
A19: 18 | B19: Marco Reus | C19: Midfield | D19: CM | E19: Dortmund | F19: 85 | G19: 30 | H19: M. Reus | I19: Marco Reus | J19: 85 | K19: 85 | L19: 33500000 | M19: CAM,CF,RM | N19: CAM | O19: Germany | P19: https://cdn.sofifa.net/players/188/350/23_60.png | Q19: 33 | R19: 180 | S19: 71 | T19: 2154 | U19: 441 | V19: Borussia Dortmund | W19: 78000 | X19: 57000000 | Y19: CAM | Z19: 2023 | AA19: 11 | AB19: 2012 | AC19: - | AD19: Right | AE19: 4 | AF19: 4 | AG19: 4 | AH19: Germany | AI19: https://cdn.sofifa.net/flags/de.png | AJ19: SUB | AK19: 11 | AL19: High | AM19: Medium | AN19: 70 | AO19: 84 | AP19: 84 | AQ19: 85 | AR19: 53 | AS19: 65 | AT19: 84 | AU19: 84 | AV19: 44 | AW19: 85 | AX19: 87 | AY19: 86 | AZ19: 88 | BA19: 85 | BB19: 79 | BC19: 86 | BD19: 75 | BE19: 66 | BF19: 83 | BG19: 86 | BH19: 81 | BI19: 86 | BJ19: 68 | BK19: 72 | BL19: 66 | BM19: 81 | BN19: 51 | BO19: 56 | BP19: 84 | BQ19: 86 | BR19: 79 | BS19: 86 | BT19: 59 | BU19: 47 | BV19: 59 | BW19: 12 | BX19: 12 | BY19: 13 | BZ19: 13 | CA19: 11 | CB19: 82 | CC19: 83 | CD19: 83 | CE19: 83 | CF19: 83 | CG19: 83 | CH19: 85 | CI19: 85 | CJ19: 83 | CK19: 85 | CL19: 74 | CM19: 72 | CN19: 74 | CO19: 70 | CP19: 62 | CQ19: 70 | CR19: 23
A20: 19 | B20: Jorginho | C20: Midfield | D20: CDM | E20: Arsenal | F20: 85 | G20: 30 | H20: Jorginho | I20: Luiz Frello Filho Jorge | J20: 85 | K20: 85 | L20: 51500000 | M20: CM | N20: CM | O20: Italy | P20: https://cdn.sofifa.net/players/205/498/23_60.png | Q20: 30 | R20: 180 | S20: 68 | T20: 2128 | U20: 434 | V20: Chelsea | W20: 165000 | X20: 95300000 | Y20: CM | Z20: 2023 | AA20: 5 | AB20: 2018 | AC20: - | AD20: Right | AE20: 3 | AF20: 3 | AG20: 2 | AH20: Italy | AI20: https://cdn.sofifa.net/flags/it.png | AJ20: CM | AK20: 8 | AL20: Medium | AM20: Medium | AN20: 54 | AO20: 67 | AP20: 86 | AQ20: 81 | AR20: 73 | AS20: 73 | AT20: 75 | AU20: 64 | AV20: 56 | AW20: 92 | AX20: 71 | AY20: 79 | AZ20: 75 | BA20: 76 | BB20: 89 | BC20: 87 | BD20: 63 | BE20: 47 | BF20: 75 | BG20: 82 | BH20: 72 | BI20: 71 | BJ20: 58 | BK20: 87 | BL20: 66 | BM20: 62 | BN20: 79 | BO20: 81 | BP20: 69 | BQ20: 88 | BR20: 89 | BS20: 84 | BT20: 67 | BU20: 81 | BV20: 71 | BW20: 14 | BX20: 7 | BY20: 13 | BZ20: 14 | CA20: 8 | CB20: 72 | CC20: 75 | CD20: 75 | CE20: 75 | CF20: 75 | CG20: 75 | CH20: 82 | CI20: 80 | CJ20: 85 | CK20: 80 | CL20: 80 | CM20: 84 | CN20: 80 | CO20: 77 | CP20: 75 | CQ20: 77 | CR20: 21
A21: 20 | B21: Pedri | C21: Midfield | D21: CM | E21: Barcelona | F21: 85 | G21: 30 | H21: Pedri | I21: Pedro González López | J21: 85 | K21: 93 | L21: 116000000 | M21: CM | N21: CM | O21: Spain | P21: https://cdn.sofifa.net/players/251/854/23_60.png | Q21: 19 | R21: 174 | S21: 61 | T21: 2109 | U21: 455 | V21: FC Barcelona | W21: 115000 | X21: 261000000 | Y21: CM | Z21: 2026 | AA21: 8 | AB21: 2020 | AC21: - | AD21: Right | AE21: 4 | AF21: 4 | AG21: 2 | AH21: Spain | AI21: https://cdn.sofifa.net/flags/es.png | AJ21: CM | AK21: 10 | AL21: High | AM21: High | AN21: 79 | AO21: 67 | AP21: 81 | AQ21: 87 | AR21: 68 | AS21: 73 | AT21: 68 | AU21: 68 | AV21: 50 | AW21: 87 | AX21: 56 | AY21: 87 | AZ21: 79 | BA21: 62 | BB21: 85 | BC21: 88 | BD21: 82 | BE21: 76 | BF21: 88 | BG21: 85 | BH21: 90 | BI21: 66 | BJ21: 65 | BK21: 88 | BL21: 70 | BM21: 67 | BN21: 62 | BO21: 72 | BP21: 77 | BQ21: 88 | BR21: 53 | BS21: 87 | BT21: 68 | BU21: 73 | BV21: 63 | BW21: 12 | BX21: 7 | BY21: 11 | BZ21: 8 | CA21: 8 | CB21: 76 | CC21: 81 | CD21: 80 | CE21: 80 | CF21: 80 | CG21: 81 | CH21: 85 | CI21: 84 | CJ21: 86 | CK21: 84 | CL21: 79 | CM21: 80 | CN21: 79 | CO21: 77 | CP21: 72 | CQ21: 77 | CR21: 19
A22: 21 | B22: Martin Odegard | C22: Midfield | D22: CAM | E22: Arsenal | F22: 85 | G22: 30 | H22: M. Ødegaard | I22: Martin Ødegaard | J22: 84 | K22: 89 | L22: 63500000 | M22: CAM,CM | N22: CAM | O22: Norway | P22: https://cdn.sofifa.net/players/222/665/23_60.png | Q22: 23 | R22: 178 | S22: 68 | T22: 2109 | U22: 442 | V22: Arsenal | W22: 105000 | X22: 125400000 | Y22: CAM | Z22: 2026 | AA22: 8 | AB22: 2021 | AC22: - | AD22: Left | AE22: 2 | AF22: 5 | AG22: 3 | AH22: Norway | AI22: https://cdn.sofifa.net/flags/no.png | AJ22: CM | AK22: 10 | AL22: High | AM22: Medium | AN22: 76 | AO22: 75 | AP22: 86 | AQ22: 84 | AR22: 58 | AS22: 63 | AT22: 84 | AU22: 75 | AV22: 52 | AW22: 88 | AX22: 76 | AY22: 85 | AZ22: 83 | BA22: 85 | BB22: 84 | BC22: 85 | BD22: 78 | BE22: 75 | BF22: 85 | BG22: 74 | BH22: 83 | BI22: 76 | BJ22: 46 | BK22: 79 | BL22: 56 | BM22: 77 | BN22: 63 | BO22: 65 | BP22: 79 | BQ22: 86 | BR22: 63 | BS22: 78 | BT22: 65 | BU22: 49 | BV22: 51 | BW22: 14 | BX22: 15 | BY22: 15 | BZ22: 8 | CA22: 10 | CB22: 78 | CC22: 82 | CD22: 80 | CE22: 80 | CF22: 80 | CG22: 82 | CH22: 86 | CI22: 85 | CJ22: 84 | CK22: 85 | CL22: 75 | CM22: 74 | CN22: 75 | CO22: 72 | CP22: 64 | CQ22: 72 | CR22: 22
A23: 22 | B23: Florian Writz | C23: Midfield | D23: CAM | E23: Bayern Leverkusen | F23: 85 | G23: 30 | H23: F. Wirtz | I23: Florian Wirtz | J23: 82 | K23: 91 | L23: 66000000 | M23: CAM,CM | N23: CAM | O23: Germany | P23: https://cdn.sofifa.net/players/256/630/23_60.png | Q23: 19 | R23: 176 | S23: 72 | T23: 1994 | U23: 428 | V23: Bayer 04 Leverkusen | W23: 38000 | X23: 125400000 | Y23: RES | Z23: 2027 | AA23: 27 | AB23: 2020 | AC23: - | AD23: Right | AE23: 4 | AF23: 4 | AG23: 2 | AH23: - | AI23: https://cdn.sofifa.net/flags/de.png | AJ23: - | AK23: - | AL23: High | AM23: Medium | AN23: 78 | AO23: 73 | AP23: 80 | AQ23: 86 | AR23: 51 | AS23: 60 | AT23: 77 | AU23: 78 | AV23: 39 | AW23: 82 | AX23: 68 | AY23: 86 | AZ23: 76 | BA23: 54 | BB23: 82 | BC23: 88 | BD23: 76 | BE23: 79 | BF23: 85 | BG23: 80 | BH23: 82 | BI23: 67 | BJ23: 52 | BK23: 79 | BL23: 50 | BM23: 70 | BN23: 63 | BO23: 45 | BP23: 78 | BQ23: 85 | BR23: 60 | BS23: 80 | BT23: 55 | BU23: 57 | BV23: 44 | BW23: 14 | BX23: 14 | BY23: 13 | BZ23: 6 | CA23: 10 | CB23: 75 | CC23: 81 | CD23: 80 | CE23: 80 | CF23: 80 | CG23: 81 | CH23: 84 | CI23: 84 | CJ23: 81 | CK23: 84 | CL23: 71 | CM23: 70 | CN23: 71 | CO23: 67 | CP23: 58 | CQ23: 67 | CR23: 21
A24: 23 | B24: James Maddison | C24: Midfield | D24: CAM | E24: Leicester City | F24: 84 | G24: 30 | H24: J. Maddison | I24: James Maddison | J24: 82 | K24: 84 | L24: 38000000 | M24: CAM,RM | N24: CAM | O24: England | P24: https://cdn.sofifa.net/players/220/697/23_60.png | Q24: 25 | R24: 175 | S24: 73 | T24: 2090 | U24: 436 | V24: Leicester City | W24: 100000 | X24: 75100000 | Y24: RM | Z24: 2024 | AA24: 10 | AB24: 2018 | AC24: - | AD24: Right | AE24: 4 | AF24: 4 | AG24: 1 | AH24: - | AI24: https://cdn.sofifa.net/flags/gb-eng.png | AJ24: - | AK24: - | AL24: High | AM24: Medium | AN24: 73 | AO24: 78 | AP24: 84 | AQ24: 85 | AR24: 54 | AS24: 62 | AT24: 81 | AU24: 76 | AV24: 35 | AW24: 84 | AX24: 73 | AY24: 85 | AZ24: 86 | BA24: 84 | BB24: 83 | BC24: 86 | BD24: 77 | BE24: 69 | BF24: 84 | BG24: 78 | BH24: 83 | BI24: 83 | BJ24: 51 | BK24: 76 | BL24: 53 | BM24: 80 | BN24: 68 | BO24: 44 | BP24: 81 | BQ24: 85 | BR24: 74 | BS24: 84 | BT24: 59 | BU24: 65 | BV24: 42 | BW24: 11 | BX24: 14 | BY24: 14 | BZ24: 12 | CA24: 14 | CB24: 76 | CC24: 81 | CD24: 80 | CE24: 80 | CF24: 80 | CG24: 81 | CH24: 84 | CI24: 83 | CJ24: 82 | CK24: 83 | CL24: 71 | CM24: 71 | CN24: 71 | CO24: 67 | CP24: 59 | CQ24: 67 | CR24: 22
A25: 24 | B25: Declan Rice | C25: Midfield | D25: CDM | E25: Arsenal | F25: 84 | G25: 30 | H25: D. Rice | I25: Declan Rice | J25: 84 | K25: 87 | L25: 52000000 | M25: CDM | N25: CDM | O25: England | P25: https://cdn.sofifa.net/players/234/378/23_60.png | Q25: 23 | R25: 185 | S25: 80 | T25: 2075 | U25: 450 | V25: West Ham United | W25: 83000 | X25: 102700000 | Y25: CDM | Z25: 2024 | AA25: 41 | AB25: 2016 | AC25: - | AD25: Right | AE25: 3 | AF25: 2 | AG25: 1 | AH25: England | AI25: https://cdn.sofifa.net/flags/gb-eng.png | AJ25: CM | AK25: 4 | AL25: Medium | AM25: High | AN25: 71 | AO25: 64 | AP25: 74 | AQ25: 76 | AR25: 82 | AS25: 83 | AT25: 55 | AU25: 61 | AV25: 72 | AW25: 83 | AX25: 50 | AY25: 78 | AZ25: 58 | BA25: 58 | BB25: 84 | BC25: 79 | BD25: 68 | BE25: 74 | BF25: 55 | BG25: 81 | BH25: 67 | BI25: 74 | BJ25: 74 | BK25: 90 | BL25: 79 | BM25: 65 | BN25: 84 | BO25: 85 | BP25: 58 | BQ25: 79 | BR25: 71 | BS25: 83 | BT25: 82 | BU25: 84 | BV25: 80 | BW25: 8 | BX25: 11 | BY25: 14 | BZ25: 5 | CA25: 9 | CB25: 72 | CC25: 71 | CD25: 73 | CE25: 73 | CF25: 73 | CG25: 71 | CH25: 77 | CI25: 76 | CJ25: 81 | CK25: 76 | CL25: 80 | CM25: 85 | CN25: 80 | CO25: 81 | CP25: 83 | CQ25: 81 | CR25: 19
A26: 25 | B26: Youri Tielemans | C26: Midfield | D26: CM | E26: Aston Villa | F26: 84 | G26: 30 | H26: Y. Tielemans | I26: Youri Tielemans | J26: 84 | K26: 86 | L26: 52500000 | M26: CM,CDM | N26: CM | O26: Belgium | P26: https://cdn.sofifa.net/players/216/393/23_60.png | Q26: 25 | R26: 176 | S26: 72 | T26: 2187 | U26: 446 | V26: Leicester City | W26: 115000 | X26: 103700000 | Y26: CM | Z26: 2023 | AA26: 8 | AB26: 2019 | AC26: - | AD26: Right | AE26: 5 | AF26: 4 | AG26: 2 | AH26: Belgium | AI26: https://cdn.sofifa.net/flags/be.png | AJ26: CM | AK26: 8 | AL26: Medium | AM26: Medium | AN26: 56 | AO26: 80 | AP26: 86 | AQ26: 81 | AR26: 70 | AS26: 73 | AT26: 82 | AU26: 74 | AV26: 67 | AW26: 89 | AX26: 79 | AY26: 81 | AZ26: 84 | BA26: 78 | BB26: 88 | BC26: 85 | BD26: 58 | BE26: 54 | BF26: 67 | BG26: 84 | BH26: 77 | BI26: 87 | BJ26: 68 | BK26: 85 | BL26: 69 | BM26: 87 | BN26: 69 | BO26: 71 | BP26: 80 | BQ26: 87 | BR26: 77 | BS26: 85 | BT26: 69 | BU26: 73 | BV26: 68 | BW26: 6 | BX26: 8 | BY26: 10 | BZ26: 14 | CA26: 12 | CB26: 79 | CC26: 79 | CD26: 80 | CE26: 80 | CF26: 80 | CG26: 79 | CH26: 84 | CI26: 82 | CJ26: 86 | CK26: 82 | CL26: 78 | CM26: 81 | CN26: 78 | CO26: 76 | CP26: 74 | CQ26: 76 | CR26: 20
A27: 26 | B27: Marcos Llorente | C27: Midfield | D27: CM | E27: Atletico de Madrid | F27: 84 | G27: 30 | H27: Marcos Llorente | I27: Marcos Llorente Moreno | J27: 84 | K27: 85 | L27: 48000000 | M27: CM,RM,RB | N27: CAM | O27: Spain | P27: https://cdn.sofifa.net/players/226/161/23_60.png | Q27: 27 | R27: 184 | S27: 74 | T27: 2244 | U27: 489 | V27: Atlético de Madrid | W27: 81000 | X27: 102000000 | Y27: SUB | Z27: 2027 | AA27: 14 | AB27: 2019 | AC27: - | AD27: Right | AE27: 4 | AF27: 3 | AG27: 3 | AH27: Spain | AI27: https://cdn.sofifa.net/flags/es.png | AJ27: SUB | AK27: 6 | AL27: High | AM27: Medium | AN27: 88 | AO27: 79 | AP27: 81 | AQ27: 82 | AR27: 78 | AS27: 81 | AT27: 74 | AU27: 80 | AV27: 67 | AW27: 86 | AX27: 66 | AY27: 82 | AZ27: 75 | BA27: 63 | BB27: 81 | BC27: 84 | BD27: 85 | BE27: 90 | BF27: 82 | BG27: 85 | BH27: 68 | BI27: 84 | BJ27: 69 | BK27: 90 | BL27: 77 | BM27: 77 | BN27: 82 | BO27: 81 | BP27: 84 | BQ27: 84 | BR27: 65 | BS27: 83 | BT27: 79 | BU27: 79 | BV27: 74 | BW27: 13 | BX27: 6 | BY27: 6 | BZ27: 11 | CA27: 15 | CB27: 84 | CC27: 83 | CD27: 83 | CE27: 83 | CF27: 83 | CG27: 83 | CH27: 85 | CI27: 85 | CJ27: 85 | CK27: 85 | CL27: 85 | CM27: 85 | CN27: 85 | CO27: 84 | CP27: 81 | CQ27: 84 | CR27: 22
A28: 27 | B28: Thomas Partey | C28: Midfield | D28: CDM | E28: Arsenal | F28: 84 | G28: 30 | H28: T. Partey | I28: Thomas Partey | J28: 84 | K28: 84 | L28: 36000000 | M28: CDM,CM | N28: CDM | O28: Ghana | P28: https://cdn.sofifa.net/players/209/989/23_60.png | Q28: 29 | R28: 185 | S28: 77 | T28: 2143 | U28: 460 | V28: Arsenal | W28: 115000 | X28: 68400000 | Y28: CDM | Z28: 2024 | AA28: 5 | AB28: 2020 | AC28: - | AD28: Right | AE28: 3 | AF28: 3 | AG28: 2 | AH28: Ghana | AI28: https://cdn.sofifa.net/flags/gh.png | AJ28: CDM | AK28: 6 | AL28: Medium | AM28: High | AN28: 65 | AO28: 71 | AP28: 81 | AQ28: 80 | AR28: 80 | AS28: 83 | AT28: 74 | AU28: 66 | AV28: 68 | AW28: 85 | AX28: 56 | AY28: 84 | AZ28: 69 | BA28: 70 | BB28: 85 | BC28: 83 | BD28: 61 | BE28: 68 | BF28: 67 | BG28: 82 | BH28: 50 | BI28: 86 | BJ28: 83 | BK28: 82 | BL28: 84 | BM28: 78 | BN28: 84 | BO28: 81 | BP28: 70 | BQ28: 85 | BR28: 49 | BS28: 86 | BT28: 80 | BU28: 84 | BV28: 80 | BW28: 11 | BX28: 13 | BY28: 9 | BZ28: 9 | CA28: 7 | CB28: 77 | CC28: 77 | CD28: 78 | CE28: 78 | CF28: 78 | CG28: 77 | CH28: 81 | CI28: 80 | CJ28: 84 | CK28: 80 | CL28: 82 | CM28: 84 | CN28: 82 | CO28: 81 | CP28: 83 | CQ28: 81 | CR28: 20
A29: 28 | B29: Sandro Tonali | C29: Midfield | D29: CM | E29: Newcastle United | F29: 84 | G29: 30 | H29: S. Tonali | I29: Sandro Tonali | J29: 84 | K29: 90 | L29: 62500000 | M29: CDM,CM | N29: CDM | O29: Italy | P29: https://cdn.sofifa.net/players/241/096/23_60.png | Q29: 22 | R29: 181 | S29: 79 | T29: 2225 | U29: 475 | V29: AC Milan | W29: 75000 | X29: 118800000 | Y29: CM | Z29: 2027 | AA29: 8 | AB29: 2021 | AC29: - | AD29: Right | AE29: 4 | AF29: 3 | AG29: 1 | AH29: - | AI29: https://cdn.sofifa.net/flags/it.png | AJ29: - | AK29: - | AL29: Medium | AM29: High | AN29: 81 | AO29: 73 | AP29: 81 | AQ29: 79 | AR29: 79 | AS29: 82 | AT29: 78 | AU29: 69 | AV29: 70 | AW29: 84 | AX29: 68 | AY29: 75 | AZ29: 75 | BA29: 81 | BB29: 81 | BC29: 83 | BD29: 78 | BE29: 83 | BF29: 81 | BG29: 82 | BH29: 83 | BI29: 79 | BJ29: 65 | BK29: 85 | BL29: 81 | BM29: 81 | BN29: 84 | BO29: 81 | BP29: 75 | BQ29: 78 | BR29: 64 | BS29: 84 | BT29: 81 | BU29: 81 | BV29: 75 | BW29: 13 | BX29: 9 | BY29: 8 | BZ29: 7 | CA29: 7 | CB29: 78 | CC29: 78 | CD29: 78 | CE29: 78 | CF29: 78 | CG29: 78 | CH29: 81 | CI29: 81 | CJ29: 83 | CK29: 81 | CL29: 83 | CM29: 84 | CN29: 83 | CO29: 82 | CP29: 81 | CQ29: 82 | CR29: 19
A30: 29 | B30: Hakan Calhanoglu | C30: Midfield | D30: CAM | E30: Inter Milan | F30: 84 | G30: 30 | H30: H. Çalhanoğlu | I30: Hakan Çalhanoğlu | J30: 84 | K30: 84 | L30: 42000000 | M30: CM | N30: CM | O30: Turkey | P30: https://cdn.sofifa.net/players/208/128/23_60.png | Q30: 28 | R30: 178 | S30: 76 | T30: 2172 | U30: 450 | V30: Inter | W30: 100000 | X30: 69300000 | Y30: CM | Z30: 2024 | AA30: 20 | AB30: 2021 | AC30: - | AD30: Right | AE30: 4 | AF30: 4 | AG30: 3 | AH30: - | AI30: https://cdn.sofifa.net/flags/tr.png | AJ30: - | AK30: - | AL30: High | AM30: High | AN30: 67 | AO30: 80 | AP30: 85 | AQ30: 86 | AR30: 68 | AS30: 64 | AT30: 80 | AU30: 75 | AV30: 53 | AW30: 87 | AX30: 74 | AY30: 86 | AZ30: 85 | BA30: 85 | BB30: 84 | BC30: 88 | BD30: 72 | BE30: 62 | BF30: 83 | BG30: 84 | BH30: 79 | BI30: 85 | BJ30: 45 | BK30: 78 | BL30: 55 | BM30: 87 | BN30: 73 | BO30: 76 | BP30: 79 | BQ30: 86 | BR30: 81 | BS30: 83 | BT30: 69 | BU30: 68 | BV30: 63 | BW30: 9 | BX30: 14 | BY30: 11 | BZ30: 6 | CA30: 10 | CB30: 79 | CC30: 81 | CD30: 82 | CE30: 82 | CF30: 82 | CG30: 81 | CH30: 84 | CI30: 84 | CJ30: 84 | CK30: 84 | CL30: 79 | CM30: 80 | CN30: 79 | CO30: 76 | CP30: 71 | CQ30: 76 | CR30: 21
A31: 30 | B31: Pierre-Emile Hojbjerg | C31: Midfield | D31: CDM | E31: Spurs | F31: 84 | G31: 30 | H31: P. Højbjerg | I31: Pierre-Emile Højbjerg | J31: 83 | K31: 85 | L31: 40500000 | M31: CDM,CM | N31: CDM | O31: Denmark | P31: https://cdn.sofifa.net/players/213/648/23_60.png | Q31: 26 | R31: 187 | S31: 84 | T31: 2108 | U31: 444 | V31: Tottenham Hotspur | W31: 110000 | X31: 80000000 | Y31: CM | Z31: 2025 | AA31: 5 | AB31: 2020 | AC31: - | AD31: Right | AE31: 4 | AF31: 3 | AG31: 2 | AH31: Denmark | AI31: https://cdn.sofifa.net/flags/dk.png | AJ31: CM | AK31: 23 | AL31: High | AM31: High | AN31: 55 | AO31: 73 | AP31: 77 | AQ31: 77 | AR31: 80 | AS31: 82 | AT31: 68 | AU31: 68 | AV31: 65 | AW31: 83 | AX31: 64 | AY31: 78 | AZ31: 70 | BA31: 74 | BB31: 81 | BC31: 80 | BD31: 56 | BE31: 54 | BF31: 65 | BG31: 84 | BH31: 67 | BI31: 85 | BJ31: 65 | BK31: 87 | BL31: 79 | BM31: 80 | BN31: 87 | BO31: 82 | BP31: 68 | BQ31: 73 | BR31: 56 | BS31: 84 | BT31: 83 | BU31: 84 | BV31: 72 | BW31: 9 | BX31: 7 | BY31: 12 | BZ31: 11 | CA31: 11 | CB31: 75 | CC31: 73 | CD31: 74 | CE31: 74 | CF31: 74 | CG31: 73 | CH31: 77 | CI31: 76 | CJ31: 82 | CK31: 76 | CL31: 79 | CM31: 84 | CN31: 79 | CO31: 78 | CP31: 81 | CQ31: 78 | CR31: 20
A32: 31 | B32: Maddison | C32: Midfield | D32: CAM | E32: Spurs | F32: 84 | G32: 30 | H32: J. Maddison | I32: James Maddison | J32: 82 | K32: 84 | L32: 38000000 | M32: CAM,RM | N32: CAM | O32: England | P32: https://cdn.sofifa.net/players/220/697/23_60.png | Q32: 25 | R32: 175 | S32: 73 | T32: 2090 | U32: 436 | V32: Leicester City | W32: 100000 | X32: 75100000 | Y32: RM | Z32: 2024 | AA32: 10 | AB32: 2018 | AC32: - | AD32: Right | AE32: 4 | AF32: 4 | AG32: 1 | AH32: - | AI32: https://cdn.sofifa.net/flags/gb-eng.png | AJ32: - | AK32: - | AL32: High | AM32: Medium | AN32: 73 | AO32: 78 | AP32: 84 | AQ32: 85 | AR32: 54 | AS32: 62 | AT32: 81 | AU32: 76 | AV32: 35 | AW32: 84 | AX32: 73 | AY32: 85 | AZ32: 86 | BA32: 84 | BB32: 83 | BC32: 86 | BD32: 77 | BE32: 69 | BF32: 84 | BG32: 78 | BH32: 83 | BI32: 83 | BJ32: 51 | BK32: 76 | BL32: 53 | BM32: 80 | BN32: 68 | BO32: 44 | BP32: 81 | BQ32: 85 | BR32: 74 | BS32: 84 | BT32: 59 | BU32: 65 | BV32: 42 | BW32: 11 | BX32: 14 | BY32: 14 | BZ32: 12 | CA32: 14 | CB32: 76 | CC32: 81 | CD32: 80 | CE32: 80 | CF32: 80 | CG32: 81 | CH32: 84 | CI32: 83 | CJ32: 82 | CK32: 83 | CL32: 71 | CM32: 71 | CN32: 71 | CO32: 67 | CP32: 59 | CQ32: 67 | CR32: 22
A33: 32 | B33: De Paul | C33: Midfield | D33: CM | E33: Atletico Madrid | F33: 84 | G33: 30 | H33: R. De Paul | I33: Rodrigo Javier De Paul | J33: 84 | K33: 84 | L33: 42000000 | M33: CM | N33: CM | O33: Argentina | P33: https://cdn.sofifa.net/players/212/616/23_60.png | Q33: 28 | R33: 180 | S33: 70 | T33: 2240 | U33: 476 | V33: Atlético de Madrid | W33: 85000 | X33: 86100000 | Y33: CM | Z33: 2026 | AA33: 5 | AB33: 2021 | AC33: - | AD33: Right | AE33: 3 | AF33: 4 | AG33: 1 | AH33: Argentina | AI33: https://cdn.sofifa.net/flags/ar.png | AJ33: CM | AK33: 7 | AL33: High | AM33: Medium | AN33: 78 | AO33: 77 | AP33: 83 | AQ33: 82 | AR33: 75 | AS33: 81 | AT33: 78 | AU33: 76 | AV33: 58 | AW33: 85 | AX33: 71 | AY33: 82 | AZ33: 84 | BA33: 76 | BB33: 85 | BC33: 85 | BD33: 80 | BE33: 76 | BF33: 78 | BG33: 81 | BH33: 80 | BI33: 80 | BJ33: 68 | BK33: 91 | BL33: 80 | BM33: 78 | BN33: 76 | BO33: 79 | BP33: 78 | BQ33: 86 | BR33: 66 | BS33: 81 | BT33: 71 | BU33: 81 | BV33: 75 | BW33: 13 | BX33: 12 | BY33: 10 | BZ33: 7 | CA33: 14 | CB33: 79 | CC33: 81 | CD33: 81 | CE33: 81 | CF33: 81 | CG33: 81 | CH33: 84 | CI33: 84 | CJ33: 84 | CK33: 84 | CL33: 82 | CM33: 83 | CN33: 82 | CO33: 81 | CP33: 78 | CQ33: 81 | CR33: 21
A34: 33 | B34: Carrasco | C34: Midfield | D34: LM | E34: Atletico Madrid | F34: 84 | G34: 30 | H34: Y. Carrasco | I34: Yannick Carrasco | J34: 85 | K34: 85 | L34: 54500000 | M34: LM | N34: LM | O34: Belgium | P34: https://cdn.sofifa.net/players/208/418/23_60.png | Q34: 28 | R34: 181 | S34: 73 | T34: 2153 | U34: 458 | V34: Atlético de Madrid | W34: 90000 | X34: 111700000 | Y34: LM | Z34: 2024 | AA34: 21 | AB34: 2020 | AC34: - | AD34: Right | AE34: 4 | AF34: 4 | AG34: 3 | AH34: Belgium | AI34: https://cdn.sofifa.net/flags/be.png | AJ34: LM | AK34: 11 | AL34: High | AM34: High | AN34: 89 | AO34: 82 | AP34: 80 | AQ34: 87 | AR34: 53 | AS34: 67 | AT34: 81 | AU34: 81 | AV34: 53 | AW34: 80 | AX34: 74 | AY34: 90 | AZ34: 87 | BA34: 80 | BB34: 74 | BC34: 86 | BD34: 89 | BE34: 89 | BF34: 87 | BG34: 81 | BH34: 71 | BI34: 85 | BJ34: 71 | BK34: 79 | BL34: 61 | BM34: 82 | BN34: 65 | BO34: 47 | BP34: 82 | BQ34: 80 | BR34: 81 | BS34: 84 | BT34: 44 | BU34: 64 | BV34: 60 | BW34: 9 | BX34: 11 | BY34: 9 | BZ34: 10 | CA34: 10 | CB34: 82 | CC34: 84 | CD34: 83 | CE34: 83 | CF34: 83 | CG34: 84 | CH34: 85 | CI34: 85 | CJ34: 82 | CK34: 85 | CL34: 75 | CM34: 71 | CN34: 75 | CO34: 72 | CP34: 64 | CQ34: 72 | CR34: 21
A35: 34 | B35: Bruno Guimaraes | C35: Midfield | D35: CDM | E35: New Castle United | F35: 83 | G35: 20 | H35: Bruno Guimarães | I35: Bruno Guimarães Moura | J35: 81 | K35: 86 | L35: 38500000 | M35: CM,CDM | N35: CM | O35: Brazil | P35: https://cdn.sofifa.net/players/247/851/23_60.png | Q35: 24 | R35: 182 | S35: 74 | T35: 2110 | U35: 449 | V35: Newcastle United | W35: 88000 | X35: 76000000 | Y35: CM | Z35: 2026 | AA35: 39 | AB35: 2022 | AC35: - | AD35: Right | AE35: 2 | AF35: 3 | AG35: 2 | AH35: - | AI35: https://cdn.sofifa.net/flags/br.png | AJ35: - | AK35: - | AL35: High | AM35: High | AN35: 69 | AO35: 67 | AP35: 79 | AQ35: 81 | AR35: 76 | AS35: 77 | AT35: 68 | AU35: 68 | AV35: 61 | AW35: 84 | AX35: 66 | AY35: 81 | AZ35: 75 | BA35: 62 | BB35: 83 | BC35: 82 | BD35: 68 | BE35: 69 | BF35: 74 | BG35: 80 | BH35: 78 | BI35: 64 | BJ35: 62 | BK35: 84 | BL35: 75 | BM35: 67 | BN35: 77 | BO35: 78 | BP35: 72 | BQ35: 82 | BR35: 65 | BS35: 83 | BT35: 77 | BU35: 79 | BV35: 74 | BW35: 7 | BX35: 11 | BY35: 15 | BZ35: 11 | CA35: 11 | CB35: 74 | CC35: 76 | CD35: 76 | CE35: 76 | CF35: 76 | CG35: 76 | CH35: 80 | CI35: 79 | CJ35: 83 | CK35: 79 | CL35: 79 | CM35: 82 | CN35: 79 | CO35: 78 | CP35: 77 | CQ35: 78 | CR35: 20
A36: 35 | B36: Rodri | C36: Midfield | D36: CDM | E36: Manchester City | F36: 83 | G36: 20 | H36: Rodri | I36: Rodrigo Hernández Cascante | J36: 87 | K36: 89 | L36: 88500000 | M36: CDM | N36: CDM | O36: Spain | P36: https://cdn.sofifa.net/players/231/866/23_60.png | Q36: 26 | R36: 191 | S36: 82 | T36: 2133 | U36: 454 | V36: Manchester City | W36: 200000 | X36: 170400000 | Y36: CDM | Z36: 2027 | AA36: 16 | AB36: 2019 | AC36: - | AD36: Right | AE36: 4 | AF36: 3 | AG36: 3 | AH36: Spain | AI36: https://cdn.sofifa.net/flags/es.png | AJ36: SUB | AK36: 16 | AL36: Medium | AM36: High | AN36: 58 | AO36: 72 | AP36: 78 | AQ36: 79 | AR36: 83 | AS36: 84 | AT36: 63 | AU36: 64 | AV36: 80 | AW36: 86 | AX36: 59 | AY36: 78 | AZ36: 65 | BA36: 61 | BB36: 83 | BC36: 85 | BD36: 54 | BE36: 62 | BF36: 65 | BG36: 82 | BH36: 65 | BI36: 89 | BJ36: 72 | BK36: 88 | BL36: 84 | BM36: 82 | BN36: 82 | BO36: 83 | BP36: 75 | BQ36: 83 | BR36: 46 | BS36: 85 | BT36: 84 | BU36: 86 | BV36: 78 | BW36: 10 | BX36: 10 | BY36: 7 | BZ36: 14 | CA36: 8 | CB36: 79 | CC36: 74 | CD36: 77 | CE36: 77 | CF36: 77 | CG36: 74 | CH36: 82 | CI36: 79 | CJ36: 86 | CK36: 79 | CL36: 82 | CM36: 87 | CN36: 82 | CO36: 82 | CP36: 85 | CQ36: 82 | CR36: 21
A37: 36 | B37: Mason Mount | C37: Midfield | D37: CAM | E37: Manchester United | F37: 83 | G37: 20 | H37: M. Mount | I37: Mason Mount | J37: 84 | K37: 87 | L37: 57500000 | M37: CAM,RW | N37: CAM | O37: England | P37: https://cdn.sofifa.net/players/233/064/23_60.png | Q37: 23 | R37: 180 | S37: 74 | T37: 2119 | U37: 444 | V37: Chelsea | W37: 130000 | X37: 110700000 | Y37: RW | Z37: 2024 | AA37: 19 | AB37: 2016 | AC37: - | AD37: Right | AE37: 4 | AF37: 3 | AG37: 3 | AH37: England | AI37: https://cdn.sofifa.net/flags/gb-eng.png | AJ37: CAM | AK37: 19 | AL37: High | AM37: High | AN37: 74 | AO37: 81 | AP37: 85 | AQ37: 82 | AR37: 55 | AS37: 67 | AT37: 83 | AU37: 81 | AV37: 59 | AW37: 87 | AX37: 75 | AY37: 82 | AZ37: 82 | BA37: 84 | BB37: 84 | BC37: 85 | BD37: 76 | BE37: 72 | BF37: 77 | BG37: 84 | BH37: 76 | BI37: 81 | BJ37: 54 | BK37: 86 | BL37: 58 | BM37: 83 | BN37: 68 | BO37: 59 | BP37: 82 | BQ37: 83 | BR37: 69 | BS37: 84 | BT37: 55 | BU37: 57 | BV37: 41 | BW37: 11 | BX37: 12 | BY37: 13 | BZ37: 8 | CA37: 12 | CB37: 81 | CC37: 82 | CD37: 82 | CE37: 82 | CF37: 82 | CG37: 82 | CH37: 86 | CI37: 85 | CJ37: 85 | CK37: 85 | CL37: 74 | CM37: 74 | CN37: 74 | CO37: 71 | CP37: 64 | CQ37: 71 | CR37: 22
A38: 37 | B38: Kai Havertz | C38: Midfield | D38: CAM | E38: Arsenal | F38: 83 | G38: 20 | H38: K. Havertz | I38: Kai Havertz | J38: 84 | K38: 91 | L38: 84500000 | M38: CAM,CF,ST | N38: CAM | O38: Germany | P38: https://cdn.sofifa.net/players/235/790/23_60.png | Q38: 23 | R38: 189 | S38: 82 | T38: 2042 | U38: 434 | V38: Chelsea | W38: 130000 | X38: 173200000 | Y38: LW | Z38: 2025 | AA38: 29 | AB38: 2020 | AC38: - | AD38: Left | AE38: 4 | AF38: 4 | AG38: 3 | AH38: Germany | AI38: https://cdn.sofifa.net/flags/de.png | AJ38: SUB | AK38: 7 | AL38: Medium | AM38: Medium | AN38: 81 | AO38: 79 | AP38: 79 | AQ38: 84 | AR38: 45 | AS38: 66 | AT38: 74 | AU38: 81 | AV38: 80 | AW38: 84 | AX38: 80 | AY38: 85 | AZ38: 84 | BA38: 53 | BB38: 79 | BC38: 85 | BD38: 76 | BE38: 85 | BF38: 77 | BG38: 84 | BH38: 75 | BI38: 74 | BJ38: 75 | BK38: 77 | BL38: 69 | BM38: 78 | BN38: 42 | BO38: 38 | BP38: 82 | BQ38: 82 | BR38: 73 | BS38: 84 | BT38: 39 | BU38: 46 | BV38: 38 | BW38: 6 | BX38: 8 | BY38: 11 | BZ38: 10 | CA38: 12 | CB38: 84 | CC38: 82 | CD38: 82 | CE38: 82 | CF38: 82 | CG38: 82 | CH38: 86 | CI38: 85 | CJ38: 81 | CK38: 85 | CL38: 68 | CM38: 66 | CN38: 68 | CO38: 65 | CP38: 59 | CQ38: 65 | CR38: 20
A39: 38 | B39: Mateo Kovacic | C39: Midfield | D39: CM | E39: Manchester City | F39: 83 | G39: 20 | H39: M. Kovačić | I39: Mateo Kovačić | J39: 84 | K39: 84 | L39: 42000000 | M39: CM | N39: CM | O39: Croatia | P39: https://cdn.sofifa.net/players/207/410/23_60.png | Q39: 28 | R39: 176 | S39: 80 | T39: 2141 | U39: 452 | V39: Chelsea | W39: 155000 | X39: 77700000 | Y39: SUB | Z39: 2024 | AA39: 8 | AB39: 2019 | AC39: - | AD39: Right | AE39: 4 | AF39: 4 | AG39: 3 | AH39: Croatia | AI39: https://cdn.sofifa.net/flags/hr.png | AJ39: CM | AK39: 8 | AL39: High | AM39: High | AN39: 70 | AO39: 69 | AP39: 83 | AQ39: 88 | AR39: 71 | AS39: 71 | AT39: 73 | AU39: 61 | AV39: 42 | AW39: 90 | AX39: 76 | AY39: 89 | AZ39: 79 | BA39: 70 | BB39: 84 | BC39: 89 | BD39: 77 | BE39: 65 | BF39: 86 | BG39: 82 | BH39: 84 | BI39: 79 | BJ39: 75 | BK39: 79 | BL39: 65 | BM39: 75 | BN39: 77 | BO39: 75 | BP39: 73 | BQ39: 86 | BR39: 59 | BS39: 84 | BT39: 73 | BU39: 76 | BV39: 68 | BW39: 9 | BX39: 5 | BY39: 6 | BZ39: 7 | CA39: 7 | CB39: 75 | CC39: 80 | CD39: 79 | CE39: 79 | CF39: 79 | CG39: 80 | CH39: 84 | CI39: 84 | CJ39: 84 | CK39: 84 | CL39: 81 | CM39: 83 | CN39: 81 | CO39: 78 | CP39: 74 | CQ39: 78 | CR39: 18
A40: 39 | B40: Thomas Lemar | C40: Midfield | D40: LM | E40: Atletico Madrid | F40: 83 | G40: 20 | H40: T. Lemar | I40: Thomas Lemar | J40: 83 | K40: 86 | L40: 47000000 | M40: CM,LM,RM | N40: CAM | O40: France | P40: https://cdn.sofifa.net/players/213/565/23_60.png | Q40: 26 | R40: 171 | S40: 66 | T40: 2215 | U40: 462 | V40: Atlético de Madrid | W40: 74000 | X40: 99900000 | Y40: SUB | Z40: 2023 | AA40: 11 | AB40: 2018 | AC40: - | AD40: Left | AE40: 3 | AF40: 4 | AG40: 3 | AH40: - | AI40: https://cdn.sofifa.net/flags/fr.png | AJ40: - | AK40: - | AL40: High | AM40: High | AN40: 82 | AO40: 78 | AP40: 83 | AQ40: 87 | AR40: 68 | AS40: 64 | AT40: 82 | AU40: 77 | AV40: 54 | AW40: 84 | AX40: 77 | AY40: 88 | AZ40: 85 | BA40: 81 | BB40: 80 | BC40: 86 | BD40: 84 | BE40: 81 | BF40: 90 | BG40: 82 | BH40: 85 | BI40: 79 | BJ40: 68 | BK40: 80 | BL40: 56 | BM40: 79 | BN40: 63 | BO40: 78 | BP40: 81 | BQ40: 85 | BR40: 69 | BS40: 80 | BT40: 55 | BU40: 77 | BV40: 69 | BW40: 11 | BX40: 15 | BY40: 13 | BZ40: 7 | CA40: 14 | CB40: 80 | CC40: 83 | CD40: 82 | CE40: 82 | CF40: 82 | CG40: 83 | CH40: 86 | CI40: 86 | CJ40: 86 | CK40: 86 | CL40: 81 | CM40: 79 | CN40: 81 | CO40: 79 | CP40: 72 | CQ40: 79 | CR40: 23
...

Sheet Auction_Log
A1: Search: | B1: mess
A2: {=IF($B$1="", "", IFERROR(TRANSPOSE(_xlfn._xlws.FILTER(Master_List!$A$2:$A$200, ISNUMBER(SEARCH($B$1, Master_List!$B$2:$B$200)))), ""))} -> 84
A3: {=IF($B$1="", "", IFERROR(TRANSPOSE(_xlfn._xlws.FILTER(Master_List!$B$2:$B$200, ISNUMBER(SEARCH($B$1, Master_List!$B$2:$B$200)))), ""))} -> Lionel Messi
A5: Player ID | B5: Player Sold | C5: Category | D5: Winning Team No | E5: Sale Price
B6: =IF(A6="","", _xlfn.XLOOKUP(A6, Master_List!A:A, Master_List!B:B, "Invalid ID")) | C6: =IF(B6="","",_xlfn.XLOOKUP(B6, Master_List!B:B, Master_List!C:C, "Not Found"))
B7: =IF(A7="","", _xlfn.XLOOKUP(A7, Master_List!A:A, Master_List!B:B, "Invalid ID")) | C7: =IF(B7="","",_xlfn.XLOOKUP(B7, Master_List!B:B, Master_List!C:C, "Not Found"))
B8: =IF(A8="","", _xlfn.XLOOKUP(A8, Master_List!A:A, Master_List!B:B, "Invalid ID")) | C8: =IF(B8="","",_xlfn.XLOOKUP(B8, Master_List!B:B, Master_List!C:C, "Not Found"))
B9: =IF(A9="","", _xlfn.XLOOKUP(A9, Master_List!A:A, Master_List!B:B, "Invalid ID")) | C9: =IF(B9="","",_xlfn.XLOOKUP(B9, Master_List!B:B, Master_List!C:C, "Not Found"))
B10: =IF(A10="","", _xlfn.XLOOKUP(A10, Master_List!A:A, Master_List!B:B, "Invalid ID")) | C10: =IF(B10="","",_xlfn.XLOOKUP(B10, Master_List!B:B, Master_List!C:C, "Not Found"))
B11: =IF(A11="","", _xlfn.XLOOKUP(A11, Master_List!A:A, Master_List!B:B, "Invalid ID")) | C11: =IF(B11="","",_xlfn.XLOOKUP(B11, Master_List!B:B, Master_List!C:C, "Not Found"))
B12: =IF(A12="","", _xlfn.XLOOKUP(A12, Master_List!A:A, Master_List!B:B, "Invalid ID")) | C12: =IF(B12="","",_xlfn.XLOOKUP(B12, Master_List!B:B, Master_List!C:C, "Not Found"))
B13: =IF(A13="","", _xlfn.XLOOKUP(A13, Master_List!A:A, Master_List!B:B, "Invalid ID")) | C13: =IF(B13="","",_xlfn.XLOOKUP(B13, Master_List!B:B, Master_List!C:C, "Not Found"))
B14: =IF(A14="","", _xlfn.XLOOKUP(A14, Master_List!A:A, Master_List!B:B, "Invalid ID")) | C14: =IF(B14="","",_xlfn.XLOOKUP(B14, Master_List!B:B, Master_List!C:C, "Not Found"))
B15: =IF(A15="","", _xlfn.XLOOKUP(A15, Master_List!A:A, Master_List!B:B, "Invalid ID")) | C15: =IF(B15="","",_xlfn.XLOOKUP(B15, Master_List!B:B, Master_List!C:C, "Not Found"))
B16: =IF(A16="","", _xlfn.XLOOKUP(A16, Master_List!A:A, Master_List!B:B, "Invalid ID")) | C16: =IF(B16="","",_xlfn.XLOOKUP(B16, Master_List!B:B, Master_List!C:C, "Not Found"))
B17: =IF(A17="","", _xlfn.XLOOKUP(A17, Master_List!A:A, Master_List!B:B, "Invalid ID")) | C17: =IF(B17="","",_xlfn.XLOOKUP(B17, Master_List!B:B, Master_List!C:C, "Not Found"))
... B307: =IF(A307="","", _xlfn.XLOOKUP(A307, Master_List!A:A, Master_List!B:B, "Invalid ID")) | C307: =IF(B307="","",_xlfn.XLOOKUP(B307, Master_List!B:B, Master_List!C:C, "Not Found"))
C308: =IF(B308="","",_xlfn.XLOOKUP(B308, Master_List!B:B, Master_List!C:C, "Not Found"))
C309: =IF(B309="","",_xlfn.XLOOKUP(B309, Master_List!B:B, Master_List!C:C, "Not Found"))
C310: =IF(B310="","",_xlfn.XLOOKUP(B310, Master_List!B:B, Master_List!C:C, "Not Found"))

Sheet Dashboard
A1: Team No | B1: Team Name | C1: Starting Purse | D1: Total Spent | E1: Remaining Purse | F1: Roster Size | G1: Forwards | H1: Midfield | I1: Defender | J1: Goalkeeper | K1: Squad Status
A2: 1 | B2: A | C2: 900 | D2: =SUMIF(Auction_Log!D:D, A2, Auction_Log!E:E) -> 0 | E2: =C2-D2 -> 900 | F2: =COUNTIF(Auction_Log!D:D, A2) -> 0 | G2: =COUNTIFS(Auction_Log!D:D, A2, Auction_Log!C:C, "Forwards") -> 0 | H2: =COUNTIFS(Auction_Log!D:D, A2, Auction_Log!C:C, "Midfield") -> 0 | I2: =COUNTIFS(Auction_Log!D:D, A2, Auction_Log!C:C, "Defender") -> 0 | J2: =COUNTIFS(Auction_Log!D:D, A2, Auction_Log!C:C, "Goalkeeper") -> 0 | K2: =IF(F2>16, "🛑 OVER MAX (16)", IF(G2>4, "🛑 MAX FW (4)", IF(H2>5, "🛑 MAX MF (5)", IF(I2>5, "🛑 MAX DF (5)", IF(J2>2, "🛑 MAX GK (2)", IF(AND(F2>=11, G2>=2, H2>=2, I2>=3, J2>=1), "✅ COMPLETE", "⏳ DRAFTING")))))) -> ⏳ DRAFTING
A3: 2 | B3: B | C3: 900 | D3: =SUMIF(Auction_Log!D:D, A3, Auction_Log!E:E) -> 0 | E3: =C3-D3 -> 900 | F3: =COUNTIF(Auction_Log!D:D, A3) -> 0 | G3: =COUNTIFS(Auction_Log!D:D, A3, Auction_Log!C:C, "Forwards") -> 0 | H3: =COUNTIFS(Auction_Log!D:D, A3, Auction_Log!C:C, "Midfield") -> 0 | I3: =COUNTIFS(Auction_Log!D:D, A3, Auction_Log!C:C, "Defender") -> 0 | J3: =COUNTIFS(Auction_Log!D:D, A3, Auction_Log!C:C, "Goalkeeper") -> 0 | K3: =IF(F3>16, "🛑 OVER MAX (16)", IF(G3>4, "🛑 MAX FW (4)", IF(H3>5, "🛑 MAX MF (5)", IF(I3>5, "🛑 MAX DF (5)", IF(J3>2, "🛑 MAX GK (2)", IF(AND(F3>=11, G3>=2, H3>=2, I3>=3, J3>=1), "✅ COMPLETE", "⏳ DRAFTING")))))) -> ⏳ DRAFTING
A4: 3 | B4: C | C4: 900 | D4: =SUMIF(Auction_Log!D:D, A4, Auction_Log!E:E) -> 0 | E4: =C4-D4 -> 900 | F4: =COUNTIF(Auction_Log!D:D, A4) -> 0 | G4: =COUNTIFS(Auction_Log!D:D, A4, Auction_Log!C:C, "Forwards") -> 0 | H4: =COUNTIFS(Auction_Log!D:D, A4, Auction_Log!C:C, "Midfield") -> 0 | I4: =COUNTIFS(Auction_Log!D:D, A4, Auction_Log!C:C, "Defender") -> 0 | J4: =COUNTIFS(Auction_Log!D:D, A4, Auction_Log!C:C, "Goalkeeper") -> 0 | K4: =IF(F4>16, "🛑 OVER MAX (16)", IF(G4>4, "🛑 MAX FW (4)", IF(H4>5, "🛑 MAX MF (5)", IF(I4>5, "🛑 MAX DF (5)", IF(J4>2, "🛑 MAX GK (2)", IF(AND(F4>=11, G4>=2, H4>=2, I4>=3, J4>=1), "✅ COMPLETE", "⏳ DRAFTING")))))) -> ⏳ DRAFTING
A5: 4 | B5: D | C5: 900 | D5: =SUMIF(Auction_Log!D:D, A5, Auction_Log!E:E) -> 0 | E5: =C5-D5 -> 900 | F5: =COUNTIF(Auction_Log!D:D, A5) -> 0 | G5: =COUNTIFS(Auction_Log!D:D, A5, Auction_Log!C:C, "Forwards") -> 0 | H5: =COUNTIFS(Auction_Log!D:D, A5, Auction_Log!C:C, "Midfield") -> 0 | I5: =COUNTIFS(Auction_Log!D:D, A5, Auction_Log!C:C, "Defender") -> 0 | J5: =COUNTIFS(Auction_Log!D:D, A5, Auction_Log!C:C, "Goalkeeper") -> 0 | K5: =IF(F5>16, "🛑 OVER MAX (16)", IF(G5>4, "🛑 MAX FW (4)", IF(H5>5, "🛑 MAX MF (5)", IF(I5>5, "🛑 MAX DF (5)", IF(J5>2, "🛑 MAX GK (2)", IF(AND(F5>=11, G5>=2, H5>=2, I5>=3, J5>=1), "✅ COMPLETE", "⏳ DRAFTING")))))) -> ⏳ DRAFTING
A6: 5 | B6: E | C6: 900 | D6: =SUMIF(Auction_Log!D:D, A6, Auction_Log!E:E) -> 0 | E6: =C6-D6 -> 900 | F6: =COUNTIF(Auction_Log!D:D, A6) -> 0 | G6: =COUNTIFS(Auction_Log!D:D, A6, Auction_Log!C:C, "Forwards") -> 0 | H6: =COUNTIFS(Auction_Log!D:D, A6, Auction_Log!C:C, "Midfield") -> 0 | I6: =COUNTIFS(Auction_Log!D:D, A6, Auction_Log!C:C, "Defender") -> 0 | J6: =COUNTIFS(Auction_Log!D:D, A6, Auction_Log!C:C, "Goalkeeper") -> 0 | K6: =IF(F6>16, "🛑 OVER MAX (16)", IF(G6>4, "🛑 MAX FW (4)", IF(H6>5, "🛑 MAX MF (5)", IF(I6>5, "🛑 MAX DF (5)", IF(J6>2, "🛑 MAX GK (2)", IF(AND(F6>=11, G6>=2, H6>=2, I6>=3, J6>=1), "✅ COMPLETE", "⏳ DRAFTING")))))) -> ⏳ DRAFTING
A7: 6 | B7: F | C7: 900 | D7: =SUMIF(Auction_Log!D:D, A7, Auction_Log!E:E) -> 0 | E7: =C7-D7 -> 900 | F7: =COUNTIF(Auction_Log!D:D, A7) -> 0 | G7: =COUNTIFS(Auction_Log!D:D, A7, Auction_Log!C:C, "Forwards") -> 0 | H7: =COUNTIFS(Auction_Log!D:D, A7, Auction_Log!C:C, "Midfield") -> 0 | I7: =COUNTIFS(Auction_Log!D:D, A7, Auction_Log!C:C, "Defender") -> 0 | J7: =COUNTIFS(Auction_Log!D:D, A7, Auction_Log!C:C, "Goalkeeper") -> 0 | K7: =IF(F7>16, "🛑 OVER MAX (16)", IF(G7>4, "🛑 MAX FW (4)", IF(H7>5, "🛑 MAX MF (5)", IF(I7>5, "🛑 MAX DF (5)", IF(J7>2, "🛑 MAX GK (2)", IF(AND(F7>=11, G7>=2, H7>=2, I7>=3, J7>=1), "✅ COMPLETE", "⏳ DRAFTING")))))) -> ⏳ DRAFTING
A8: 7 | B8: G | C8: 900 | D8: =SUMIF(Auction_Log!D:D, A8, Auction_Log!E:E) -> 0 | E8: =C8-D8 -> 900 | F8: =COUNTIF(Auction_Log!D:D, A8) -> 0 | G8: =COUNTIFS(Auction_Log!D:D, A8, Auction_Log!C:C, "Forwards") -> 0 | H8: =COUNTIFS(Auction_Log!D:D, A8, Auction_Log!C:C, "Midfield") -> 0 | I8: =COUNTIFS(Auction_Log!D:D, A8, Auction_Log!C:C, "Defender") -> 0 | J8: =COUNTIFS(Auction_Log!D:D, A8, Auction_Log!C:C, "Goalkeeper") -> 0 | K8: =IF(F8>16, "🛑 OVER MAX (16)", IF(G8>4, "🛑 MAX FW (4)", IF(H8>5, "🛑 MAX MF (5)", IF(I8>5, "🛑 MAX DF (5)", IF(J8>2, "🛑 MAX GK (2)", IF(AND(F8>=11, G8>=2, H8>=2, I8>=3, J8>=1), "✅ COMPLETE", "⏳ DRAFTING")))))) -> ⏳ DRAFTING
A9: 8 | B9: H | C9: 900 | D9: =SUMIF(Auction_Log!D:D, A9, Auction_Log!E:E) -> 0 | E9: =C9-D9 -> 900 | F9: =COUNTIF(Auction_Log!D:D, A9) -> 0 | G9: =COUNTIFS(Auction_Log!D:D, A9, Auction_Log!C:C, "Forwards") -> 0 | H9: =COUNTIFS(Auction_Log!D:D, A9, Auction_Log!C:C, "Midfield") -> 0 | I9: =COUNTIFS(Auction_Log!D:D, A9, Auction_Log!C:C, "Defender") -> 0 | J9: =COUNTIFS(Auction_Log!D:D, A9, Auction_Log!C:C, "Goalkeeper") -> 0 | K9: =IF(F9>16, "🛑 OVER MAX (16)", IF(G9>4, "🛑 MAX FW (4)", IF(H9>5, "🛑 MAX MF (5)", IF(I9>5, "🛑 MAX DF (5)", IF(J9>2, "🛑 MAX GK (2)", IF(AND(F9>=11, G9>=2, H9>=2, I9>=3, J9>=1), "✅ COMPLETE", "⏳ DRAFTING")))))) -> ⏳ DRAFTING
A10: 9 | B10: I | C10: 900 | D10: =SUMIF(Auction_Log!D:D, A10, Auction_Log!E:E) -> 0 | E10: =C10-D10 -> 900 | F10: =COUNTIF(Auction_Log!D:D, A10) -> 0 | G10: =COUNTIFS(Auction_Log!D:D, A10, Auction_Log!C:C, "Forwards") -> 0 | H10: =COUNTIFS(Auction_Log!D:D, A10, Auction_Log!C:C, "Midfield") -> 0 | I10: =COUNTIFS(Auction_Log!D:D, A10, Auction_Log!C:C, "Defender") -> 0 | J10: =COUNTIFS(Auction_Log!D:D, A10, Auction_Log!C:C, "Goalkeeper") -> 0 | K10: =IF(F10>16, "🛑 OVER MAX (16)", IF(G10>4, "🛑 MAX FW (4)", IF(H10>5, "🛑 MAX MF (5)", IF(I10>5, "🛑 MAX DF (5)", IF(J10>2, "🛑 MAX GK (2)", IF(AND(F10>=11, G10>=2, H10>=2, I10>=3, J10>=1), "✅ COMPLETE", "⏳ DRAFTING")))))) -> ⏳ DRAFTING
A11: 10 | B11: J | C11: 900 | D11: =SUMIF(Auction_Log!D:D, A11, Auction_Log!E:E) -> 0 | E11: =C11-D11 -> 900 | F11: =COUNTIF(Auction_Log!D:D, A11) -> 0 | G11: =COUNTIFS(Auction_Log!D:D, A11, Auction_Log!C:C, "Forwards") -> 0 | H11: =COUNTIFS(Auction_Log!D:D, A11, Auction_Log!C:C, "Midfield") -> 0 | I11: =COUNTIFS(Auction_Log!D:D, A11, Auction_Log!C:C, "Defender") -> 0 | J11: =COUNTIFS(Auction_Log!D:D, A11, Auction_Log!C:C, "Goalkeeper") -> 0 | K11: =IF(F11>16, "🛑 OVER MAX (16)", IF(G11>4, "🛑 MAX FW (4)", IF(H11>5, "🛑 MAX MF (5)", IF(I11>5, "🛑 MAX DF (5)", IF(J11>2, "🛑 MAX GK (2)", IF(AND(F11>=11, G11>=2, H11>=2, I11>=3, J11>=1), "✅ COMPLETE", "⏳ DRAFTING")))))) -> ⏳ DRAFTING

Sheet Team Profile
A1: Team: | B1: 1
A2: Team Name | B2: Starting Purse | C2: Total Spent | D2: Remaining | E2: Total Roster
A3: =_xlfn.XLOOKUP(B1, Dashboard!A2:A11, Dashboard!B2:B11, "Team " & B1) -> A | B3: =_xlfn.XLOOKUP(B1, Dashboard!A2:A11, Dashboard!C2:C11, 0) -> 900 | C3: =_xlfn.XLOOKUP(B1, Dashboard!A2:A11, Dashboard!D2:D11, 0) -> 0 | D3: =_xlfn.XLOOKUP(B1, Dashboard!A2:A11, Dashboard!E2:E11, 0) -> 900 | E3: =_xlfn.XLOOKUP(B1, Dashboard!A2:A11, Dashboard!F2:F11, 0) & " / 16" -> 0 / 16
A4: Position Role | B4: Drafted | C4: Min Requirement | D4: Min Needed | E4: Max Cap | F4: Max Extra
A5: Forwards (FW) | B5: =COUNTIFS(Auction_Log!D5:D200, B1, Auction_Log!C5:C200, "Forwards") -> 0 | C5: 2 | D5: =MAX(0, 2 - B5) -> 2 | E5: 4 | F5: =MAX(0, 4 - B5) -> 4
A6: Midfielders (MF) | B6: =COUNTIFS(Auction_Log!D5:D200, B1, Auction_Log!C5:C200, "Midfield") -> 0 | C6: 2 | D6: =MAX(0, 2 - B6) -> 2 | E6: 5 | F6: =MAX(0, 5 - B6) -> 5
A7: Defenders (DF) | B7: =COUNTIFS(Auction_Log!D5:D200, B1, Auction_Log!C5:C200, "Defender") -> 0 | C7: 3 | D7: =MAX(0, 3 - B7) -> 3 | E7: 5 | F7: =MAX(0, 5 - B7) -> 5
A8: Goalkeepers (GK) | B8: =COUNTIFS(Auction_Log!D5:D200, B1, Auction_Log!C5:C200, "Goalkeeper") -> 0 | C8: 1 | D8: =MAX(0, 1 - B8) -> 1 | E8: 2 | F8: =MAX(0, 2 - B8) -> 2
A9: TOTAL SQUAD | B9: =SUM(B5:B8) -> 0 | C9: 8 | D9: =SUM(D5:D8) -> 8 | E9: 16 | F9: =16 - B9 -> 16
